2023-07-06 23:16:52,899 INFO    StreamThr :18906 [internal.py:wandb_internal():89] W&B internal server running at pid: 18906, started at: 2023-07-06 23:16:52.898733
2023-07-06 23:16:52,901 DEBUG   HandlerThread:18906 [handler.py:handle_request():144] handle_request: status
2023-07-06 23:16:52,909 INFO    WriterThread:18906 [datastore.py:open_for_write():85] open: /home/ubuntu/Documents/working/Hangers.AI/DemandFocasting/gtm_implement/wandb/run-20230706_231652-vpqz2okp/run-vpqz2okp.wandb
2023-07-06 23:16:52,910 DEBUG   SenderThread:18906 [sender.py:send():369] send: header
2023-07-06 23:16:52,911 DEBUG   SenderThread:18906 [sender.py:send():369] send: run
2023-07-06 23:16:53,436 ERROR   SenderThread:18906 [internal_api.py:execute():323] 403 response executing GraphQL.
2023-07-06 23:16:53,436 ERROR   SenderThread:18906 [internal_api.py:execute():324] {"errors":[{"message":"permission denied","path":["upsertBucket"],"extensions":{"code":"PERMISSION_ERROR"}}],"data":{"upsertBucket":null}}
2023-07-06 23:16:53,436 ERROR   SenderThread:18906 [sender.py:send_run():955] It appears that you do not have permission to access the requested resource. Please reach out to the project owner to grant you access. If you have the correct permissions, verify that there are no issues with your networking setup.(Error 403: Forbidden)
Traceback (most recent call last):
  File "/home/ubuntu/Documents/working/Hangers.AI/.venv/lib/python3.7/site-packages/wandb/sdk/lib/retry.py", line 131, in __call__
    result = self._call_fn(*args, **kwargs)
  File "/home/ubuntu/Documents/working/Hangers.AI/.venv/lib/python3.7/site-packages/wandb/sdk/internal/internal_api.py", line 320, in execute
    return self.client.execute(*args, **kwargs)  # type: ignore
  File "/home/ubuntu/Documents/working/Hangers.AI/.venv/lib/python3.7/site-packages/wandb/vendor/gql-0.2.0/wandb_gql/client.py", line 52, in execute
    result = self._get_result(document, *args, **kwargs)
  File "/home/ubuntu/Documents/working/Hangers.AI/.venv/lib/python3.7/site-packages/wandb/vendor/gql-0.2.0/wandb_gql/client.py", line 60, in _get_result
    return self.transport.execute(document, *args, **kwargs)
  File "/home/ubuntu/Documents/working/Hangers.AI/.venv/lib/python3.7/site-packages/wandb/sdk/lib/gql_request.py", line 56, in execute
    request.raise_for_status()
  File "/home/ubuntu/Documents/working/Hangers.AI/.venv/lib/python3.7/site-packages/requests/models.py", line 1021, in raise_for_status
    raise HTTPError(http_error_msg, response=self)
requests.exceptions.HTTPError: 403 Client Error: Forbidden for url: https://api.wandb.ai/graphql

During handling of the above exception, another exception occurred:

Traceback (most recent call last):
  File "/home/ubuntu/Documents/working/Hangers.AI/.venv/lib/python3.7/site-packages/wandb/sdk/internal/sender.py", line 953, in send_run
    self._init_run(run, config_value_dict)
  File "/home/ubuntu/Documents/working/Hangers.AI/.venv/lib/python3.7/site-packages/wandb/sdk/internal/sender.py", line 1005, in _init_run
    commit=run.git.commit or None,
  File "/home/ubuntu/Documents/working/Hangers.AI/.venv/lib/python3.7/site-packages/wandb/apis/normalize.py", line 73, in wrapper
    raise err
  File "/home/ubuntu/Documents/working/Hangers.AI/.venv/lib/python3.7/site-packages/wandb/apis/normalize.py", line 41, in wrapper
    return func(*args, **kwargs)
  File "/home/ubuntu/Documents/working/Hangers.AI/.venv/lib/python3.7/site-packages/wandb/sdk/internal/internal_api.py", line 1731, in upsert_run
    **kwargs,
  File "/home/ubuntu/Documents/working/Hangers.AI/.venv/lib/python3.7/site-packages/wandb/sdk/internal/internal_api.py", line 295, in gql
    **kwargs,
  File "/home/ubuntu/Documents/working/Hangers.AI/.venv/lib/python3.7/site-packages/wandb/sdk/lib/retry.py", line 147, in __call__
    retry_timedelta_triggered = check_retry_fn(e)
  File "/home/ubuntu/Documents/working/Hangers.AI/.venv/lib/python3.7/site-packages/wandb/util.py", line 908, in check_retry_fn
    return fallback_retry_fn(e)
  File "/home/ubuntu/Documents/working/Hangers.AI/.venv/lib/python3.7/site-packages/wandb/util.py", line 851, in no_retry_auth
    "It appears that you do not have permission to access the requested resource. "
wandb.errors.CommError: It appears that you do not have permission to access the requested resource. Please reach out to the project owner to grant you access. If you have the correct permissions, verify that there are no issues with your networking setup.(Error 403: Forbidden)
2023-07-06 23:16:53,697 DEBUG   HandlerThread:18906 [handler.py:handle_request():144] handle_request: shutdown
2023-07-06 23:16:53,697 INFO    HandlerThread:18906 [handler.py:finish():854] shutting down handler
2023-07-06 23:16:53,911 INFO    WriterThread:18906 [datastore.py:close():298] close: /home/ubuntu/Documents/working/Hangers.AI/DemandFocasting/gtm_implement/wandb/run-20230706_231652-vpqz2okp/run-vpqz2okp.wandb
2023-07-06 23:16:54,440 INFO    SenderThread:18906 [sender.py:finish():1526] shutting down sender
